KeyError: "['name', 'gender'] not in index"
Traceback:
File "C:\Users\2358461\KPN TASK\Task - 4\venv\Lib\site-packages\streamlit\runtime\scriptrunner\exec_code.py", line 121, in exec_func_with_error_handling
    result = func()
             ^^^^^^
File "C:\Users\2358461\KPN TASK\Task - 4\venv\Lib\site-packages\streamlit\runtime\scriptrunner\script_runner.py", line 645, in code_to_exec
    exec(code, module.__dict__)
File "C:\Users\2358461\KPN TASK\Task - 4\exp6.py", line 403, in <module>
    main()
File "C:\Users\2358461\KPN TASK\Task - 4\exp6.py", line 382, in main
    output_df = output_df[final_column_order]
                ~~~~~~~~~^^^^^^^^^^^^^^^^^^^^
File "C:\Users\2358461\KPN TASK\Task - 4\venv\Lib\site-packages\pandas\core\frame.py", line 4108, in __getitem__
    indexer = self.columns._get_indexer_strict(key, "columns")[1]
              ^^^^^^^^^^^^^^^^^^^^^^^^^^^^^^^^^^^^^^^^^^^^^^^^
File "C:\Users\2358461\KPN TASK\Task - 4\venv\Lib\site-packages\pandas\core\indexes\base.py", line 6200, in _get_indexer_strict
    self._raise_if_missing(keyarr, indexer, axis_name)
File "C:\Users\2358461\KPN TASK\Task - 4\venv\Lib\site-packages\pandas\core\indexes\base.py", line 6252, in _raise_if_missing
    raise KeyError(f"{not_found} not in index")